<?xml version="1.0" encoding="utf-8"?>
<!-- This URDF was automatically created by SolidWorks to URDF Exporter! Originally created by Stephen Brawner (brawner@gmail.com) 
     Commit Version: 1.6.0-4-g7f85cfe  Build Version: 1.6.7995.38578
     For more information, please see http://wiki.ros.org/sw_urdf_exporter -->
<robot
  name="meshesotravez">
  <link
    name="base_link">
    <inertial>
      <origin
        xyz="-0.002876 -0.00013597 -0.085753"
        rpy="0 0 0" />
      <mass
        value="2.4215" />
      <inertia
        ixx="0.038812"
        ixy="2.4997E-05"
        ixz="0.00013349"
        iyy="0.038259"
        iyz="-1.0929E-18"
        izz="0.074597" />
    </inertial>
    <visual>
      <origin
        xyz="0 0 0"
        rpy="0 0 0" />
      <geometry>
        <mesh
          filename="package://meshesotravez/meshes/base_link.STL" />
      </geometry>
      <material
        name="">
        <color
          rgba="0.79216 0.81961 0.93333 1" />
      </material>
    </visual>
    <collision>
      <origin
        xyz="0 0 0"
        rpy="0 0 0" />
      <geometry>
        <mesh
          filename="package://meshesotravez/meshes/base_link.STL" />
      </geometry>
    </collision>
  </link>
  <link
    name="wheel_left_link">
    <inertial>
      <origin
        xyz="1.3352E-09 8.1843E-10 0.020002"
        rpy="0 0 0" />
      <mass
        value="0.26047" />
      <inertia
        ixx="0.00041201"
        ixy="-9.6755E-12"
        ixz="-2.527E-12"
        iyy="0.00041201"
        iyz="3.1287E-12"
        izz="0.00076355" />
    </inertial>
    <visual>
      <origin
        xyz="0 0 0"
        rpy="0 0 0" />
      <geometry>
        <mesh
          filename="package://meshesotravez/meshes/wheel_left_link.STL" />
      </geometry>
      <material
        name="">
        <color
          rgba="0.90196 0.92157 0.92157 1" />
      </material>
    </visual>
    <collision>
      <origin
        xyz="0 0 0"
        rpy="0 0 0" />
      <geometry>
        <mesh
          filename="package://meshesotravez/meshes/wheel_left_link.STL" />
      </geometry>
    </collision>
  </link>
  <joint
    name="wheel_left_joint"
    type="continuous">
    <origin
      xyz="-0.091483 0.14579 -0.185"
      rpy="-1.5708 0 0" />
    <parent
      link="base_link" />
    <child
      link="wheel_left_link" />
    <axis
      xyz="0 0 1" />
    <limit
      effort="100"
      velocity="100" />
    <dynamics
      damping="0.1"
      friction="0.1" />
  </joint>
  <link
    name="wheel_right_link">
    <inertial>
      <origin
        xyz="-1.2885E-09 8.9862E-10 -0.020002"
        rpy="0 0 0" />
      <mass
        value="0.26047" />
      <inertia
        ixx="0.00041201"
        ixy="8.7204E-12"
        ixz="-2.7551E-12"
        iyy="0.00041201"
        iyz="-2.9859E-12"
        izz="0.00076355" />
    </inertial>
    <visual>
      <origin
        xyz="0 0 0"
        rpy="0 0 0" />
      <geometry>
        <mesh
          filename="package://meshesotravez/meshes/wheel_right_link.STL" />
      </geometry>
      <material
        name="">
        <color
          rgba="0.90196 0.92157 0.92157 1" />
      </material>
    </visual>
    <collision>
      <origin
        xyz="0 0 0"
        rpy="0 0 0" />
      <geometry>
        <mesh
          filename="package://meshesotravez/meshes/wheel_right_link.STL" />
      </geometry>
    </collision>
  </link>
  <joint
    name="wheel_right_joint"
    type="continuous">
    <origin
      xyz="-0.091483 -0.14621 -0.185"
      rpy="1.5708 0 3.1416" />
    <parent
      link="base_link" />
    <child
      link="wheel_right_link" />
    <axis
      xyz="0 0 1" />
    <limit
      effort="100"
      velocity="100" />
    <dynamics
      damping="0.1"
      friction="0.1" />
  </joint>
  <link
    name="base_castor_link">
    <inertial>
      <origin
        xyz="0 -2.08166817117217E-16 0.0141762813814508"
        rpy="0 0 0" />
      <mass
        value="0.0128281265837759" />
      <inertia
        ixx="4.35042978378941E-06"
        ixy="3.92733826540723E-09"
        ixz="1.43398637306382E-21"
        iyy="4.22331083836077E-06"
        iyz="-1.23330561063615E-21"
        izz="3.9070765868801E-06" />
    </inertial>
    <visual>
      <origin
        xyz="0 0 0"
        rpy="0 0 0" />
      <geometry>
        <mesh
          filename="package://meshesotravez/meshes/base_castor_link.STL" />
      </geometry>
      <material
        name="">
        <color
          rgba="0.792156862745098 0.819607843137255 0.933333333333333 1" />
      </material>
    </visual>
    <collision>
      <origin
        xyz="0 0 0"
        rpy="0 0 0" />
      <geometry>
        <mesh
          filename="package://meshesotravez/meshes/base_castor_link.STL" />
      </geometry>
    </collision>
  </link>
  <joint
    name="base_castor_joint"
    type="continuous">
    <origin
      xyz="0.11102 -0.00020838 -0.18058"
      rpy="3.1416 0 0" />
    <parent
      link="base_link" />
    <child
      link="base_castor_link" />
    <axis
      xyz="0 0 1" />
    <limit
      effort="100"
      velocity="100" />
    <dynamics
      damping="0.1"
      friction="0.1" />
  </joint>
  <link
    name="wheel_castor_link">
    <inertial>
      <origin
        xyz="5.67686175845239E-11 -2.52227516650549E-10 -2.34009084454558E-05"
        rpy="0 0 0" />
      <mass
        value="0.0459793119455567" />
      <inertia
        ixx="1.36058585628758E-05"
        ixy="-2.60865520999119E-13"
        ixz="2.2071502932371E-13"
        iyy="1.36058594056942E-05"
        iyz="1.10966438522062E-14"
        izz="2.31589723867144E-05" />
    </inertial>
    <visual>
      <origin
        xyz="0 0 0"
        rpy="0 0 0" />
      <geometry>
        <mesh
          filename="package://meshesotravez/meshes/wheel_castor_link.STL" />
      </geometry>
      <material
        name="">
        <color
          rgba="0.901960784313726 0.92156862745098 0.92156862745098 1" />
      </material>
    </visual>
    <collision>
      <origin
        xyz="0 0 0"
        rpy="0 0 0" />
      <geometry>
        <mesh
          filename="package://meshesotravez/meshes/wheel_castor_link.STL" />
      </geometry>
    </collision>
  </link>
  <joint
    name="wheel_castor_joint"
    type="continuous">
    <origin
      xyz="0 0 0.039416"
      rpy="1.5399 -1.5708 0" />
    <parent
      link="base_castor_link" />
    <child
      link="wheel_castor_link" />
    <axis
      xyz="0 0 1" />
    <limit
      effort="100"
      velocity="100" />
    <dynamics
      damping="0.1"
      friction="0.1" />
  </joint>
</robot>