<?xml version="1.0" encoding="utf-8"?>
<!-- This URDF was automatically created by SolidWorks to URDF Exporter! Originally created by Stephen Brawner (brawner@gmail.com) 
     Commit Version: 1.6.0-4-g7f85cfe  Build Version: 1.6.7995.38578
     For more information, please see http://wiki.ros.org/sw_urdf_exporter -->
<robot
  name="meshesotravez">
  <link
    name="base_link">
    <inertial>
      <origin
        xyz="-0.002876 -0.00013597 -0.085753"
        rpy="0 0 0" />
      <mass
        value="2.4215" />
      <inertia
        ixx="0.0001"
        ixy="0"
        ixz="0"
        iyy="0.0003"
        iyz="0"
        izz="0.0002" />
    </inertial>
    <visual>
      <origin
        xyz="0 0 0"
        rpy="0 0 0" />
      <geometry>
        <mesh
          filename="package://robot_description/meshes/base_link.STL" />
      </geometry>
      <material
        name="">
        <color
          rgba="0.79216 0.81961 0.93333 1" />
      </material>
    </visual>
    <collision>
      <origin
        xyz="0 0 0"
        rpy="0 0 0" />
      <geometry>
        <mesh
          filename="package://robot_description/meshes/base_link.STL" />
      </geometry>
    </collision>
  </link>


  <!-- <gazebo>
  <mul></mul> -->

  <!-- </gazebo> -->

  <link
    name="wheel_left_link">
    <inertial>
      <origin
        xyz="1.3352E-09 8.1843E-10 0.020002"
        rpy="0 0 0" />
      <mass
        value="0.26047" />
      <inertia
        ixx="0.00002"
        ixy="0"
        ixz="0"
        iyy="0.00002"
        iyz="0"
        izz="0.0001" />
    </inertial>
    <visual>
      <origin
        xyz="0 0 0"
        rpy="0 0 0" />
      <geometry>
        <mesh
          filename="package://robot_description/meshes/wheel_left_link.STL" />
      </geometry>
      <material
        name="">
        <color
          rgba="0.90196 0.92157 0.92157 1" />
      </material>
    </visual>
    <collision>
      <origin
        xyz="0 0 0"
        rpy="0 0 0" />
      <geometry>
        <mesh
          filename="package://robot_description/meshes/wheel_left_link.STL" />
      </geometry>
    </collision>
  </link>
  <joint
    name="wheel_left_joint"
    type="continuous">
    <origin
      xyz="-0.091483 0.14579 -0.185"
      rpy="-1.5708 0 0" />
    <parent
      link="base_link" />
    <child
      link="wheel_left_link" />
    <axis
      xyz="0 0 1" />
    <limit
      effort="100"
      velocity="100" />
    <dynamics
      damping="0.1"
      friction="0.1" />
  </joint>
  <link
    name="wheel_right_link">
    <inertial>
      <origin
        xyz="-1.2885E-09 8.9862E-10 -0.020002"
        rpy="0 0 0" />
      <mass
        value="0.26047" />
      <inertia
        ixx="0.00002"
        ixy="0"
        ixz="0"
        iyy="0.00002"
        iyz="0"
        izz="0.0001" />
    </inertial>
    <visual>
      <origin
        xyz="0 0 0"
        rpy="0 0 0" />
      <geometry>
        <mesh
          filename="package://robot_description/meshes/wheel_right_link.STL" />
      </geometry>
      <material
        name="">
        <color
          rgba="0.90196 0.92157 0.92157 1" />
      </material>
    </visual>
    <collision>
      <origin
        xyz="0 0 0"
        rpy="0 0 0" />
      <geometry>
        <mesh
          filename="package://robot_description/meshes/wheel_right_link.STL" />
      </geometry>
    </collision>
  </link>
  <joint
    name="wheel_right_joint"
    type="continuous">
    <origin
      xyz="-0.091483 -0.14621 -0.185"
      rpy="1.5708 0 3.1416" />
    <parent
      link="base_link" />
    <child
      link="wheel_right_link" />
    <axis
      xyz="0 0 1" />
    <limit
      effort="100"
      velocity="100" />
    <dynamics
      damping="0.1"
      friction="0.1" />
  </joint>
  <link
    name="base_castor_link">
    <inertial>
      <origin
        xyz="0 -2.08166817117217E-16 0.0141762813814508"
        rpy="0 0 0" />
      <mass
        value="0.0128281265837759" />
      <inertia
        ixx="0.00004"
        ixy="0"
        ixz="0"
        iyy="0.00004"
        iyz="0"
        izz="0.00001" />
    </inertial>
    <visual>
      <origin
        xyz="0 0 0"
        rpy="0 0 0" />
      <geometry>
        <mesh
          filename="package://robot_description/meshes/base_castor_link.STL" />
      </geometry>
      <material
        name="">
        <color
          rgba="0.792156862745098 0.819607843137255 0.933333333333333 1" />
      </material>
    </visual>
    <collision>
      <origin
        xyz="0 0 0"
        rpy="0 0 0" />
      <geometry>
        <mesh
          filename="package://robot_description/meshes/base_castor_link.STL" />
      </geometry>
    </collision>
  </link>
  <joint
    name="base_castor_joint"
    type="continuous">
    <origin
      xyz="0.11102 -0.00020838 -0.18058"
      rpy="3.1416 0 0" />
    <parent
      link="base_link" />
    <child
      link="base_castor_link" />
    <axis
      xyz="0 0 1" />
    <limit
      effort="100"
      velocity="100" />
    <dynamics
      damping="0.1"
      friction="0.1" />
  </joint>
  <link
    name="wheel_castor_link">
    <inertial>
      <origin
        xyz="5.67686175845239E-11 -2.52227516650549E-10 -2.34009084454558E-05"
        rpy="0 0 0" />
      <mass
        value="0.0459793119455567" />
      <inertia
        ixx="0.00004"
        ixy="0"
        ixz="0"
        iyy="0.00004"
        iyz="0"
        izz="0.0001" />
    </inertial>
    <visual>
      <origin
        xyz="0 0 0"
        rpy="0 0 0" />
      <geometry>
        <mesh
          filename="package://robot_description/meshes/wheel_castor_link.STL" />
      </geometry>
      <material
        name="">
        <color
          rgba="0.901960784313726 0.92156862745098 0.92156862745098 1" />
      </material>
    </visual>
    <collision>
      <origin
        xyz="0 0 0"
        rpy="0 0 0" />
      <geometry>
        <mesh
          filename="package://robot_description/meshes/wheel_castor_link.STL" />
      </geometry>
    </collision>
  </link>
  <joint
    name="wheel_castor_joint"
    type="continuous">
    <origin
      xyz="0 0 0.039416"
      rpy="1.5399 -1.5708 0" />
    <parent
      link="base_castor_link" />
    <child
      link="wheel_castor_link" />
    <axis
      xyz="0 0 1" />
    <limit
      effort="100"
      velocity="100" />
    <dynamics
      damping="0.1"
      friction="0.1" />
  </joint>
</robot>